Workbook

Sheet User
A1: user_id | B1: ora_user_id | C1: PI | D1: ora_group_id | E1: title | F1: first_name | G1: last_name | I1: position | J1: organisation | K1: organisation_id | L1: X | M1: department | N1: postal_address | O1: country | P1: phone | Q1: email1 | R1: email2 | S1: active_email | T1: SQL
A2: CUSR00093 | B2: CU00001 | D2: CG00039 | E2: Dr | F2: Andreas | G2: Brust | H2: =COUNTIF($G$2:$G$900,G2) -> 1 | I2: PostDoc | J2: University of Queensland | K2: =VLOOKUP(J2,Organisation!$A$2:$C$499,3,FALSE) -> CORG00001 | L2: =VLOOKUP(J2,Organisation!$A$2:$E$499,4,FALSE) -> Academic | M2: Institute for Molecular Bioscience (IMB) | O2: Australia | P2: +61 7 3346 2985 (0404518755) | Q2: a.brust@imb.uq.edu.au | S2: 0 | T2: ="Update Collaborator Set Organisation = '"&J2&"' where User_ID = '"&B2&"'; " -> Update Collaborator Set Organisation = 'University of Queensland' where User_ID = 'CU00001';
A3: CUSR00021 | B3: CU00002 | C3: Y | D3: CG00003 | E3: Dr | F3: Anna | G3: Peacock | H3: =COUNTIF($G$2:$G$900,G3) -> 1 | J3: University of Birmingham | K3: =VLOOKUP(J3,Organisation!$A$2:$C$499,3,FALSE) -> CORG00218 | L3: =VLOOKUP(J3,Organisation!$A$2:$E$499,4,FALSE) -> Academic | M3: School of Chemistry | O3: United Kingdom | P3: +44 (0)121 414 4362 | Q3: a.f.a.peacock@bham.ac.uk | S3: 1 | T3: ="Update Collaborator Set Organisation = '"&J3&"' where User_ID = '"&B3&"'; " -> Update Collaborator Set Organisation = 'University of Birmingham' where User_ID = 'CU00002'; | U3: ="Update dcollab.collab_user Set Pi = True where User_ID = '"&A3&"'; " -> Update dcollab.collab_user Set Pi = True where User_ID = 'CUSR00021';
A4: CUSR00003 | B4: CU00003 | D4: CG00002 | E4: Dr | F4: Angie | G4: Jarrad | H4: =COUNTIF($G$2:$G$900,G4) -> 1 | I4: PhD student | J4: University of Queensland | K4: =VLOOKUP(J4,Organisation!$A$2:$C$499,3,FALSE) -> CORG00001 | L4: =VLOOKUP(J4,Organisation!$A$2:$E$499,4,FALSE) -> Academic | M4: Institute for Molecular Bioscience (IMB) | O4: Australia | P4: 617334 62156 | Q4: a.jarrad@imb.uq.edu.au | S4: 0 | T4: ="Update Collaborator Set Organisation = '"&J4&"' where User_ID = '"&B4&"'; " -> Update Collaborator Set Organisation = 'University of Queensland' where User_ID = 'CU00003';
A5: CUSR00004 | B5: CU00004 | D5: CG00002 | E5: Dr | F5: Alberto Boucas | G5: Da Silva | H5: =COUNTIF($G$2:$G$900,G5) -> 1 | I5: PostDoc | J5: University of Queensland | K5: =VLOOKUP(J5,Organisation!$A$2:$C$499,3,FALSE) -> CORG00001 | L5: =VLOOKUP(J5,Organisation!$A$2:$E$499,4,FALSE) -> Academic | M5: Institute for Molecular Bioscience (IMB) | O5: Australia | P5: 334 62747 | Q5: a.silva@imb.uq.edu.au | S5: 0 | T5: ="Update Collaborator Set Organisation = '"&J5&"' where User_ID = '"&B5&"'; " -> Update Collaborator Set Organisation = 'University of Queensland' where User_ID = 'CU00004';
A6: CUSR00022 | B6: CU00005 | C6: Y | D6: CG00004 | E6: Dr | F6: Adam | G6: Renslo | H6: =COUNTIF($G$2:$G$900,G6) -> 1 | J6: University of California San Francisco | K6: =VLOOKUP(J6,Organisation!$A$2:$C$499,3,FALSE) -> CORG00222 | L6: =VLOOKUP(J6,Organisation!$A$2:$E$499,4,FALSE) -> Academic | M6: Department of Pharmaceutical Chemistry | N6: San Francisco | O6: United States of America | P6: 415-514-9698 | Q6: adam.renslo@ucsf.edu | S6: 1 | T6: ="Update Collaborator Set Organisation = '"&J6&"' where User_ID = '"&B6&"'; " -> Update Collaborator Set Organisation = 'University of California San Francisco' where User_ID = 'CU00005'; | U6: ="Update dcollab.collab_user Set Pi = True where User_ID = '"&A6&"'; " -> Update dcollab.collab_user Set Pi = True where User_ID = 'CUSR00022';
A7: CUSR00024 | B7: CU00006 | C7: Y | D7: CG00005 | E7: Prof | F7: Adolfo Jr. | G7: Horn | H7: =COUNTIF($G$2:$G$900,G7) -> 1 | J7: Universidade Estadual do Norte Fluminense Darcy Ribeiro | K7: =VLOOKUP(J7,Organisation!$A$2:$C$499,3,FALSE) -> CORG00197 | L7: =VLOOKUP(J7,Organisation!$A$2:$E$499,4,FALSE) -> Academic | M7: Laboratório de Ciência Químicas | O7: Brazil | Q7: adolfouenf@gmail.com | S7: 1 | T7: ="Update Collaborator Set Organisation = '"&J7&"' where User_ID = '"&B7&"'; " -> Update Collaborator Set Organisation = 'Universidade Estadual do Norte Fluminense Darcy Ribeiro' where User_ID = 'CU00006'; | U7: ="Update dcollab.collab_user Set Pi = True where User_ID = '"&A7&"'; " -> Update dcollab.collab_user Set Pi = True where User_ID = 'CUSR00024';
A8: CUSR00030 | B8: CU00007 | D8: CG00009 | E8: Dr | F8: Angelica | G8: Merlot | H8: =COUNTIF($G$2:$G$900,G8) -> 1 | J8: University of Sydney | K8: =VLOOKUP(J8,Organisation!$A$2:$C$499,3,FALSE) -> CORG00271 | L8: =VLOOKUP(J8,Organisation!$A$2:$E$499,4,FALSE) -> Academic | M8: School of Medical Sciences | O8: Australia | P8: +61 2 9351 6720 | Q8: angelica.merlot@sydney.edu.au | S8: 1 | T8: ="Update Collaborator Set Organisation = '"&J8&"' where User_ID = '"&B8&"'; " -> Update Collaborator Set Organisation = 'University of Sydney' where User_ID = 'CU00007';
A9: CUSR00005 | B9: CU00008 | C9: Y | D9: CG00002 | E9: Dr | F9: Avril | G9: Robertson | H9: =COUNTIF($G$2:$G$900,G9) -> 1 | J9: University of Queensland | K9: =VLOOKUP(J9,Organisation!$A$2:$C$499,3,FALSE) -> CORG00001 | L9: =VLOOKUP(J9,Organisation!$A$2:$E$499,4,FALSE) -> Academic | M9: Institute for Molecular Bioscience (IMB) | O9: Australia | P9: +61 7 3346 2204 | Q9: avril.robertson@imb.uq.edu.au | S9: 1 | T9: ="Update Collaborator Set Organisation = '"&J9&"' where User_ID = '"&B9&"'; " -> Update Collaborator Set Organisation = 'University of Queensland' where User_ID = 'CU00008'; | U9: ="Update dcollab.collab_user Set Pi = True where User_ID = '"&A9&"'; " -> Update dcollab.collab_user Set Pi = True where User_ID = 'CUSR00005';
A10: CUSR00006 | B10: CU00009 | D10: CG00002 | E10: Dr | F10: Bernd | G10: Becker | H10: =COUNTIF($G$2:$G$900,G10) -> 1 | I10: PostDoc | J10: University of Queensland | K10: =VLOOKUP(J10,Organisation!$A$2:$C$499,3,FALSE) -> CORG00001 | L10: =VLOOKUP(J10,Organisation!$A$2:$E$499,4,FALSE) -> Academic | M10: Institute for Molecular Bioscience (IMB) | O10: Australia | Q10: b.becker@imb.uq.edu.au | S10: 0 | T10: ="Update Collaborator Set Organisation = '"&J10&"' where User_ID = '"&B10&"'; " -> Update Collaborator Set Organisation = 'University of Queensland' where User_ID = 'CU00009';
A11: CUSR00060 | B11: CU00010 | D11: CG00019 | E11: Dr | F11: Barny | G11: Cox | H11: =COUNTIF($G$2:$G$900,G11) -> 1 | J11: University College London | K11: =VLOOKUP(J11,Organisation!$A$2:$C$499,3,FALSE) -> CORG00211 | L11: =VLOOKUP(J11,Organisation!$A$2:$E$499,4,FALSE) -> Academic | M11: School of Pharmacy | O11: United Kingdom | P11: +44 (0)20 7679 9000 | Q11: b.cox@uclb.com | S11: 1 | T11: ="Update Collaborator Set Organisation = '"&J11&"' where User_ID = '"&B11&"'; " -> Update Collaborator Set Organisation = 'University College London' where User_ID = 'CU00010';
A12: CUSR00119 | B12: CU00011 | D12: CG00052 | E12: Dr | F12: Barbara | G12: Grischek | H12: =COUNTIF($G$2:$G$900,G12) -> 1 | J12: University of Graz | K12: =VLOOKUP(J12,Organisation!$A$2:$C$499,3,FALSE) -> CORG00231 | L12: =VLOOKUP(J12,Organisation!$A$2:$E$499,4,FALSE) -> Academic | M12: Institute of Chemistry | O12: Austria | Q12: barbara.grischek@uni-graz.at | S12: 1 | T12: ="Update Collaborator Set Organisation = '"&J12&"' where User_ID = '"&B12&"'; " -> Update Collaborator Set Organisation = 'University of Graz' where User_ID = 'CU00011';
A13: CUSR00102 | B13: CU00012 | D13: CG00043 | E13: Dr | F13: Bruno | G13: Didier | H13: =COUNTIF($G$2:$G$900,G13) -> 1 | J13: Centre national de la recherche scientifique | K13: =VLOOKUP(J13,Organisation!$A$2:$C$499,3,FALSE) -> CORG00030 | L13: =VLOOKUP(J13,Organisation!$A$2:$E$499,4,FALSE) -> Academic | O13: France | P13: +33 3 68 85 43 20 | Q13: bdidier@unistra.fr | S13: 1 | T13: ="Update Collaborator Set Organisation = '"&J13&"' where User_ID = '"&B13&"'; " -> Update Collaborator Set Organisation = 'Centre national de la recherche scientifique' where User_ID = 'CU00012';
A14: CUSR00026 | B14: CU00013 | C14: Y | D14: CG00006 | E14: Prof | F14: Rolf | G14: Breinbauer | H14: =COUNTIF($G$2:$G$900,G14) -> 1 | J14: Technical University of Graz | K14: =VLOOKUP(J14,Organisation!$A$2:$C$499,3,FALSE) -> CORG00183 | L14: =VLOOKUP(J14,Organisation!$A$2:$E$499,4,FALSE) -> Academic | M14: Institute of Organic Chemistry | O14: Austria | P14: +43-316-873-32400 | Q14: breinbauer@tugraz.at | S14: 1 | T14: ="Update Collaborator Set Organisation = '"&J14&"' where User_ID = '"&B14&"'; " -> Update Collaborator Set Organisation = 'Technical University of Graz' where User_ID = 'CU00013'; | U14: ="Update dcollab.collab_user Set Pi = True where User_ID = '"&A14&"'; " -> Update dcollab.collab_user Set Pi = True where User_ID = 'CUSR00026';
A15: CUSR00079 | B15: CU00014 | D15: CG00030 | E15: Dr | F15: Briar | G15: Naysmith | H15: =COUNTIF($G$2:$G$900,G15) -> 1 | J15: University of Auckland | K15: =VLOOKUP(J15,Organisation!$A$2:$C$499,3,FALSE) -> CORG00216 | L15: =VLOOKUP(J15,Organisation!$A$2:$E$499,4,FALSE) -> Academic | M15: School of Chemical Sciences | O15: New Zealand | P15: +6493737599 | Q15: briar.naysmith@auckland.ac.nz | S15: 1 | T15: ="Update Collaborator Set Organisation = '"&J15&"' where User_ID = '"&B15&"'; " -> Update Collaborator Set Organisation = 'University of Auckland' where User_ID = 'CU00014';
A16: CUSR00027 | B16: CU00015 | C16: Y | D16: CG00007 | E16: Dr | F16: Colin | G16: Suckling | H16: =COUNTIF($G$2:$G$900,G16) -> 1 | J16: University of Strathclyde | K16: =VLOOKUP(J16,Organisation!$A$2:$C$499,3,FALSE) -> CORG00270 | L16: =VLOOKUP(J16,Organisation!$A$2:$E$499,4,FALSE) -> Academic | M16: Department of Pure and Applied Chemistry | O16: United Kingdom | P16: +44 (0)141 548 2271 | Q16: c.j.suckling@strath.ac.uk | S16: 1 | T16: ="Update Collaborator Set Organisation = '"&J16&"' where User_ID = '"&B16&"'; " -> Update Collaborator Set Organisation = 'University of Strathclyde' where User_ID = 'CU00015'; | U16: ="Update dcollab.collab_user Set Pi = True where User_ID = '"&A16&"'; " -> Update dcollab.collab_user Set Pi = True where User_ID = 'CUSR00027';
A17: CUSR00515 | B17: CU00016 | C17: Y | D17: CG00243 | E17: Dr | F17: Shmuel | G17: Carmeli | H17: =COUNTIF($G$2:$G$900,G17) -> 1 | J17: Tel Aviv University | K17: =VLOOKUP(J17,Organisation!$A$2:$C$499,3,FALSE) -> CORG00186 | L17: =VLOOKUP(J17,Organisation!$A$2:$E$499,4,FALSE) -> Academic | M17: School of Chemistry, Faculty of Exact Science | O17: Israel | P17: 97236408550 | Q17: carmeli@post.tau.ac.il | S17: 1 | T17: ="Update Collaborator Set Organisation = '"&J17&"' where User_ID = '"&B17&"'; " -> Update Collaborator Set Organisation = 'Tel Aviv University' where User_ID = 'CU00016'; | U17: ="Update dcollab.collab_user Set Pi = True where User_ID = '"&A17&"'; " -> Update dcollab.collab_user Set Pi = True where User_ID = 'CUSR00515';
A18: CUSR00029 | B18: CU00017 | C18: Y | D18: CG00008 | E18: Dr | F18: Cheyenne | G18: Brindle | H18: =COUNTIF($G$2:$G$900,G18) -> 1 | J18: Trinity College | K18: =VLOOKUP(J18,Organisation!$A$2:$C$499,3,FALSE) -> CORG00188 | L18: =VLOOKUP(J18,Organisation!$A$2:$E$499,4,FALSE) -> Academic | M18: Department of Chemistry | O18: United States of America | P18: 8602972479 | Q18: cheyenne.brindle@trincoll.edu | S18: 1 | T18: ="Update Collaborator Set Organisation = '"&J18&"' where User_ID = '"&B18&"'; " -> Update Collaborator Set Organisation = 'Trinity College' where User_ID = 'CU00017'; | U18: ="Update dcollab.collab_user Set Pi = True where User_ID = '"&A18&"'; " -> Update dcollab.collab_user Set Pi = True where User_ID = 'CUSR00029';
A19: CUSR00025 | B19: CU00018 | D19: CG00005 | E19: Dr | F19: Christiane | G19: Fernandes Horn | H19: =COUNTIF($G$2:$G$900,G19) -> 1 | J19: Universidade Estadual do Norte Fluminense Darcy Ribeiro | K19: =VLOOKUP(J19,Organisation!$A$2:$C$499,3,FALSE) -> CORG00197 | L19: =VLOOKUP(J19,Organisation!$A$2:$E$499,4,FALSE) -> Academic | M19: Laboratório de Ciência Químicas | O19: Brazil | Q19: chrisuenf@gmail.com | S19: 1 | T19: ="Update Collaborator Set Organisation = '"&J19&"' where User_ID = '"&B19&"'; " -> Update Collaborator Set Organisation = 'Universidade Estadual do Norte Fluminense Darcy Ribeiro' where User_ID = 'CU00018';
A20: CUSR00023 | B20: CU00019 | D20: CG00004 | E20: Dr | F20: Conor | G20: Caffrey | H20: =COUNTIF($G$2:$G$900,G20) -> 1 | J20: University of California San Francisco | K20: =VLOOKUP(J20,Organisation!$A$2:$C$499,3,FALSE) -> CORG00222 | L20: =VLOOKUP(J20,Organisation!$A$2:$E$499,4,FALSE) -> Academic | M20: Department of Pharmaceutical Chemistry | O20: United States of America | Q20: conor.caffrey@ucsf.edu | S20: 0 | T20: ="Update Collaborator Set Organisation = '"&J20&"' where User_ID = '"&B20&"'; " -> Update Collaborator Set Organisation = 'University of California San Francisco' where User_ID = 'CU00019';
A21: CUSR00031 | B21: CU00020 | C21: Y | D21: CG00009 | E21: Dr | F21: Des R. | G21: Richardson | H21: =COUNTIF($G$2:$G$900,G21) -> 1 | J21: University of Sydney | K21: =VLOOKUP(J21,Organisation!$A$2:$C$499,3,FALSE) -> CORG00271 | L21: =VLOOKUP(J21,Organisation!$A$2:$E$499,4,FALSE) -> Academic | M21: School of Medical Sciences | O21: Australia | P21: +61 2 9036 6548 | Q21: d.richardson@med.usyd.edu.au | S21: 1 | T21: ="Update Collaborator Set Organisation = '"&J21&"' where User_ID = '"&B21&"'; " -> Update Collaborator Set Organisation = 'University of Sydney' where User_ID = 'CU00020'; | U21: ="Update dcollab.collab_user Set Pi = True where User_ID = '"&A21&"'; " -> Update dcollab.collab_user Set Pi = True where User_ID = 'CUSR00031';
A22: CUSR00483 | B22: CU00021 | D22: CG00233 | E22: Dr | F22: Diana A. | G22: Zaleta-Pinet | H22: =COUNTIF($G$2:$G$900,G22) -> 1 | J22: University of Newcastle | K22: =VLOOKUP(J22,Organisation!$A$2:$C$499,3,FALSE) -> CORG00255 | L22: =VLOOKUP(J22,Organisation!$A$2:$E$499,4,FALSE) -> Academic | M22: School of Environmental and Life Sciences (Chemistry) | O22: Australia | P22: 02 49 215 464 | Q22: diana.zaletapinet@uon.edu.au | S22: 1 | T22: ="Update Collaborator Set Organisation = '"&J22&"' where User_ID = '"&B22&"'; " -> Update Collaborator Set Organisation = 'University of Newcastle' where User_ID = 'CU00021';
A23: CUSR00034 | B23: CU00022 | C23: Y | D23: CG00010 | E23: Dr | F23: Jayesh. J. | G23: Modha | H23: =COUNTIF($G$2:$G$900,G23) -> 1 | J23: Saurashtra University | K23: =VLOOKUP(J23,Organisation!$A$2:$C$499,3,FALSE) -> CORG00170 | L23: =VLOOKUP(J23,Organisation!$A$2:$E$499,4,FALSE) -> Academic | M23: Maharshi Dayanand Science College | N23: Rajkot | O23: India | P23: +91-9426944476 | Q23: drjjmodha@gmail.com | S23: 1 | T23: ="Update Collaborator Set Organisation = '"&J23&"' where User_ID = '"&B23&"'; " -> Update Collaborator Set Organisation = 'Saurashtra University' where User_ID = 'CU00022'; | U23: ="Update dcollab.collab_user Set Pi = True where User_ID = '"&A23&"'; " -> Update dcollab.collab_user Set Pi = True where User_ID = 'CUSR00034';
A24: CUSR00036 | B24: CU00023 | C24: Y | D24: CG00011 | E24: Dr | F24: Ranjan | G24: Khunt | H24: =COUNTIF($G$2:$G$900,G24) -> 1 | J24: Saurashtra University | K24: =VLOOKUP(J24,Organisation!$A$2:$C$499,3,FALSE) -> CORG00170 | L24: =VLOOKUP(J24,Organisation!$A$2:$E$499,4,FALSE) -> Academic | O24: India | P24: 91 9824831192 | Q24: drrckhunt12@yahoo.com | S24: 1 | T24: ="Update Collaborator Set Organisation = '"&J24&"' where User_ID = '"&B24&"'; " -> Update Collaborator Set Organisation = 'Saurashtra University' where User_ID = 'CU00023'; | U24: ="Update dcollab.collab_user Set Pi = True where User_ID = '"&A24&"'; " -> Update dcollab.collab_user Set Pi = True where User_ID = 'CUSR00036';
A25: CUSR00037 | B25: CU00024 | C25: Y | D25: CG00012 | E25: Dr | F25: Elizabeth | G25: Coulson | H25: =COUNTIF($G$2:$G$900,G25) -> 1 | J25: University of Queensland | K25: =VLOOKUP(J25,Organisation!$A$2:$C$499,3,FALSE) -> CORG00001 | L25: =VLOOKUP(J25,Organisation!$A$2:$E$499,4,FALSE) -> Academic | M25: Queensland Brain Institute | O25: Australia | P25: +61 7 334 66392 | Q25: elizabeth.coulson@uq.edu.au | S25: 1 | T25: ="Update Collaborator Set Organisation = '"&J25&"' where User_ID = '"&B25&"'; " -> Update Collaborator Set Organisation = 'University of Queensland' where User_ID = 'CU00024'; | U25: ="Update dcollab.collab_user Set Pi = True where User_ID = '"&A25&"'; " -> Update dcollab.collab_user Set Pi = True where User_ID = 'CUSR00037';
A26: CUSR00071 | B26: CU00025 | D26: CG00025 | E26: Dr | F26: Ewa | G26: Burchacka | H26: =COUNTIF($G$2:$G$900,G26) -> 1 | J26: University of Technology | K26: =VLOOKUP(J26,Organisation!$A$2:$C$499,3,FALSE) -> CORG00272 | L26: =VLOOKUP(J26,Organisation!$A$2:$E$499,4,FALSE) -> Academic | M26: Medicinal Chemistry and Microbiology | O26: Poland | P26: 48-71-530-269-659 | Q26: ewa.burchacka@pwr.edu.pl | S26: 1 | T26: ="Update Collaborator Set Organisation = '"&J26&"' where User_ID = '"&B26&"'; " -> Update Collaborator Set Organisation = 'University of Technology' where User_ID = 'CU00025';
A27: CUSR00028 | B27: CU00026 | D27: CG00007 | E27: Dr | F27: Fraser | G27: Scott | H27: =COUNTIF($G$2:$G$900,G27) -> 2 | J27: University of Strathclyde | K27: =VLOOKUP(J27,Organisation!$A$2:$C$499,3,FALSE) -> CORG00270 | L27: =VLOOKUP(J27,Organisation!$A$2:$E$499,4,FALSE) -> Academic | M27: Department of Pure and Applied Chemistry | O27: United Kingdom | P27: 07984101447 | Q27: fraser.j.scott@strath.ac.uk | S27: 1 | T27: ="Update Collaborator Set Organisation = '"&J27&"' where User_ID = '"&B27&"'; " -> Update Collaborator Set Organisation = 'University of Strathclyde' where User_ID = 'CU00026';
A28: CUSR00038 | B28: CU00027 | C28: Y | D28: CG00013 | E28: Dr | F28: Fred | G28: Pfeffer | H28: =COUNTIF($G$2:$G$900,G28) -> 1 | I28: PhD | J28: Deakin University | K28: =VLOOKUP(J28,Organisation!$A$2:$C$499,3,FALSE) -> CORG00048 | L28: =VLOOKUP(J28,Organisation!$A$2:$E$499,4,FALSE) -> Academic | M28: Faculty of Science Engineering and Built Environment | N28: Deakin University | O28: Australia | P28: +61-3-5227-1439 | Q28: fred.pfeffer@deakin.edu.au | S28: 1 | T28: ="Update Collaborator Set Organisation = '"&J28&"' where User_ID = '"&B28&"'; " -> Update Collaborator Set Organisation = 'Deakin University' where User_ID = 'CU00027'; | U28: ="Update dcollab.collab_user Set Pi = True where User_ID = '"&A28&"'; " -> Update dcollab.collab_user Set Pi = True where User_ID = 'CUSR00038';
A29: CUSR00041 | B29: CU00028 | C29: Y | D29: CG00014 | E29: Dr | F29: Gary | G29: Grant | H29: =COUNTIF($G$2:$G$900,G29) -> 1 | I29: Deputy Head (Learning and Teaching) | J29: Griffith University | K29: =VLOOKUP(J29,Organisation!$A$2:$C$499,3,FALSE) -> CORG00067 | L29: =VLOOKUP(J29,Organisation!$A$2:$E$499,4,FALSE) -> Academic | M29: Griffith School of Pharmacy | N29: School of Pharmacy and Pharmacology, Gold Coast Campus, Griffith University, QLD 4222 | O29: Australia | P29: 0417-706-242 | Q29: g.grant@griffith.edu.au | S29: 1 | T29: ="Update Collaborator Set Organisation = '"&J29&"' where User_ID = '"&B29&"'; " -> Update Collaborator Set Organisation = 'Griffith University' where User_ID = 'CU00028'; | U29: ="Update dcollab.collab_user Set Pi = True where User_ID = '"&A29&"'; " -> Update dcollab.collab_user Set Pi = True where User_ID = 'CUSR00041';
A30: CUSR00044 | B30: CU00029 | D30: CG00015 | E30: Dr | F30: Glenn | G30: King | H30: =COUNTIF($G$2:$G$900,G30) -> 2 | I30: Group Leader | J30: University of Queensland | K30: =VLOOKUP(J30,Organisation!$A$2:$C$499,3,FALSE) -> CORG00001 | L30: =VLOOKUP(J30,Organisation!$A$2:$E$499,4,FALSE) -> Academic | M30: Institute for Molecular Bioscience (IMB) | N30: St. Lucia, QLD 4072, Australia | O30: Australia | P30: 61733462025 | Q30: glenn.king@imb.uq.edu.au | S30: 1 | T30: ="Update Collaborator Set Organisation = '"&J30&"' where User_ID = '"&B30&"'; " -> Update Collaborator Set Organisation = 'University of Queensland' where User_ID = 'CU00029';
A31: CUSR00053 | B31: CU00030 | C31: Y | D31: CG00016 | E31: Dr | F31: Hemant Kumar | G31: Bankhede | H31: =COUNTIF($G$2:$G$900,G31) -> 1 | J31: RKDF University | K31: =VLOOKUP(J31,Organisation!$A$2:$C$499,3,FALSE) -> CORG00159 | L31: =VLOOKUP(J31,Organisation!$A$2:$E$499,4,FALSE) -> Academic | M31: Pharmaceutics | O31: India | P31: 9271280985 | Q31: hemant_16aug@yahoo.co.in | S31: 1 | T31: ="Update Collaborator Set Organisation = '"&J31&"' where User_ID = '"&B31&"'; " -> Update Collaborator Set Organisation = 'RKDF University' where User_ID = 'CU00030'; | U31: ="Update dcollab.collab_user Set Pi = True where User_ID = '"&A31&"'; " -> Update dcollab.collab_user Set Pi = True where User_ID = 'CUSR00053';
A32: CUSR00054 | B32: CU00031 | C32: Y | D32: CG00017 | E32: Dr | F32: Christopher | G32: Hulme | H32: =COUNTIF($G$2:$G$900,G32) -> 1 | J32: University of Arizona | K32: =VLOOKUP(J32,Organisation!$A$2:$C$499,3,FALSE) -> CORG00214 | L32: =VLOOKUP(J32,Organisation!$A$2:$E$499,4,FALSE) -> Academic | M32: College of Pharmacy | N32: BIO5 Translational Drug Discovery Center | O32: United States of America | P32: (520)-626-5322 | Q32: hulme@pharmacy.arizona.edu | S32: 1 | T32: ="Update Collaborator Set Organisation = '"&J32&"' where User_ID = '"&B32&"'; " -> Update Collaborator Set Organisation = 'University of Arizona' where User_ID = 'CU00031'; | U32: ="Update dcollab.collab_user Set Pi = True where User_ID = '"&A32&"'; " -> Update dcollab.collab_user Set Pi = True where User_ID = 'CUSR00054';
A33: CUSR00056 | B33: CU00032 | C33: Y | D33: CG00018 | E33: Dr | F33: James | G33: Bull | H33: =COUNTIF($G$2:$G$900,G33) -> 2 | J33: Imperial College London | K33: =VLOOKUP(J33,Organisation!$A$2:$C$499,3,FALSE) -> CORG00075 | L33: =VLOOKUP(J33,Organisation!$A$2:$E$499,4,FALSE) -> Academic | N33: South Kensington Campus, London, SW7 2AZ | O33: United Kingdom | P33: (44) 020 7594 5811 | Q33: j.bull@imperial.ac.uk | S33: 1 | T33: ="Update Collaborator Set Organisation = '"&J33&"' where User_ID = '"&B33&"'; " -> Update Collaborator Set Organisation = 'Imperial College London' where User_ID = 'CU00032'; | U33: ="Update dcollab.collab_user Set Pi = True where User_ID = '"&A33&"'; " -> Update dcollab.collab_user Set Pi = True where User_ID = 'CUSR00056';
A34: CUSR00061 | B34: CU00033 | C34: Y | D34: CG00019 | E34: Dr | F34: Jim | G34: Anderson | H34: =COUNTIF($G$2:$G$900,G34) -> 1 | J34: University College London | K34: =VLOOKUP(J34,Organisation!$A$2:$C$499,3,FALSE) -> CORG00211 | L34: =VLOOKUP(J34,Organisation!$A$2:$E$499,4,FALSE) -> Academic | M34: School of Pharmacy | O34: United Kingdom | P34: +44 (0)20 7679 5585 | Q34: j.c.anderson@ucl.ac.uk | S34: 1 | T34: ="Update Collaborator Set Organisation = '"&J34&"' where User_ID = '"&B34&"'; " -> Update Collaborator Set Organisation = 'University College London' where User_ID = 'CU00033'; | U34: ="Update dcollab.collab_user Set Pi = True where User_ID = '"&A34&"'; " -> Update dcollab.collab_user Set Pi = True where User_ID = 'CUSR00061';
A35: CUSR00063 | B35: CU00034 | C35: Y | D35: CG00020 | E35: Dr | F35: Johannes | G35: Reynisson | H35: =COUNTIF($G$2:$G$900,G35) -> 1 | I35: Group Leader | J35: University of Auckland | K35: =VLOOKUP(J35,Organisation!$A$2:$C$499,3,FALSE) -> CORG00216 | L35: =VLOOKUP(J35,Organisation!$A$2:$E$499,4,FALSE) -> Academic | M35: School of Chemical Sciences | O35: New Zealand | P35: +64 9 373 7599 | Q35: j.reynisson@auckland.ac.nz | S35: 1 | T35: ="Update Collaborator Set Organisation = '"&J35&"' where User_ID = '"&B35&"'; " -> Update Collaborator Set Organisation = 'University of Auckland' where User_ID = 'CU00034'; | U35: ="Update dcollab.collab_user Set Pi = True where User_ID = '"&A35&"'; " -> Update dcollab.collab_user Set Pi = True where User_ID = 'CUSR00063';
A36: CUSR00001 | B36: CU00035 | C36: Y | D36: CG00001 | E36: Dr | F36: Johannes | G36: Zuegg | H36: =COUNTIF($G$2:$G$900,G36) -> 1 | I36: Program Coordinator | J36: University of Queensland | K36: =VLOOKUP(J36,Organisation!$A$2:$C$499,3,FALSE) -> CORG00001 | L36: =VLOOKUP(J36,Organisation!$A$2:$E$499,4,FALSE) -> Academic | M36: Institute for Molecular Bioscience (IMB) | N36: Bld 80 Carmody Road, St Lucia 4072 | O36: Australia | P36: 61 7 3346 2994 | Q36: j.zuegg@uq.edu.au | S36: 1 | T36: ="Update Collaborator Set Organisation = '"&J36&"' where User_ID = '"&B36&"'; " -> Update Collaborator Set Organisation = 'University of Queensland' where User_ID = 'CU00035'; | U36: ="Update dcollab.collab_user Set Pi = True where User_ID = '"&A36&"'; " -> Update dcollab.collab_user Set Pi = True where User_ID = 'CUSR00001';
A37: CUSR00064 | B37: CU00036 | C37: Y | D37: CG00021 | E37: Dr | F37: Jeffrey | G37: Neitz | H37: =COUNTIF($G$2:$G$900,G37) -> 1 | J37: University of California San Francisco | K37: =VLOOKUP(J37,Organisation!$A$2:$C$499,3,FALSE) -> CORG00222 | L37: =VLOOKUP(J37,Organisation!$A$2:$E$499,4,FALSE) -> Academic | M37: Department of Pharmaceutical Chemistry | O37: United States of America | P37: 415-476-9804 | Q37: jeffrey.neitz@ucsf.edu | S37: 1 | T37: ="Update Collaborator Set Organisation = '"&J37&"' where User_ID = '"&B37&"'; " -> Update Collaborator Set Organisation = 'University of California San Francisco' where User_ID = 'CU00036'; | U37: ="Update dcollab.collab_user Set Pi = True where User_ID = '"&A37&"'; " -> Update dcollab.collab_user Set Pi = True where User_ID = 'CUSR00064';
A38: CUSR00066 | B38: CU00037 | C38: Y | D38: CG00022 | E38: Dr | F38: John | G38: Wade | H38: =COUNTIF($G$2:$G$900,G38) -> 1 | J38: University of Melbourne | K38: =VLOOKUP(J38,Organisation!$A$2:$C$499,3,FALSE) -> CORG00244 | L38: =VLOOKUP(J38,Organisation!$A$2:$E$499,4,FALSE) -> Academic | M38: Florey Institute for Neuroscience and Mental Health | O38: Australia | P38: +61 3 8344 7285 | Q38: john.wade@florey.edu.au | S38: 1 | T38: ="Update Collaborator Set Organisation = '"&J38&"' where User_ID = '"&B38&"'; " -> Update Collaborator Set Organisation = 'University of Melbourne' where User_ID = 'CU00037'; | U38: ="Update dcollab.collab_user Set Pi = True where User_ID = '"&A38&"'; " -> Update dcollab.collab_user Set Pi = True where User_ID = 'CUSR00066';
A39: CUSR00067 | B39: CU00038 | C39: Y | D39: CG00023 | E39: Dr | F39: Jonathan | G39: George | H39: =COUNTIF($G$2:$G$900,G39) -> 1 | J39: University of Adelaide | K39: =VLOOKUP(J39,Organisation!$A$2:$C$499,3,FALSE) -> CORG00212 | L39: =VLOOKUP(J39,Organisation!$A$2:$E$499,4,FALSE) -> Academic | M39: Faculty of Chemistry | O39: Australia | P39: 08 83 135 494 | Q39: jonathan.george@adelaide.edu.au | S39: 1 | T39: ="Update Collaborator Set Organisation = '"&J39&"' where User_ID = '"&B39&"'; " -> Update Collaborator Set Organisation = 'University of Adelaide' where User_ID = 'CU00038'; | U39: ="Update dcollab.collab_user Set Pi = True where User_ID = '"&A39&"'; " -> Update dcollab.collab_user Set Pi = True where User_ID = 'CUSR00067';
A40: CUSR00068 | B40: CU00039 | C40: Y | D40: CG00024 | E40: Dr | F40: Subash | G40: Jonnalgadda | H40: =COUNTIF($G$2:$G$900,G40) -> 1 | J40: Rowan University | K40: =VLOOKUP(J40,Organisation!$A$2:$C$499,3,FALSE) -> CORG00162 | L40: =VLOOKUP(J40,Organisation!$A$2:$E$499,4,FALSE) -> Academic | M40: Chemistry and Biochemistry | O40: United States of America | P40: 1-856-256-5452 | Q40: jonnalagadda@rowan.edu | S40: 1 | T40: ="Update Collaborator Set Organisation = '"&J40&"' where User_ID = '"&B40&"'; " -> Update Collaborator Set Organisation = 'Rowan University' where User_ID = 'CU00039'; | U40: ="Update dcollab.collab_user Set Pi = True where User_ID = '"&A40&"'; " -> Update dcollab.collab_user Set Pi = True where User_ID = 'CUSR00068';
...

Sheet Group
A1: ora_group_id | B1: group_id | D1: ora_pi_id | E1: organisation | F1: x1 | G1: organisation_id | I1: group_code | K1: email | L1: department | M1: postal_address | N1: country | O1: mta_document | P1: mta_status | Q1: STATUS | R1: orasql1 | S1: orasql2 | T1: sql3 | U1: sql4
A2: CG00001 | B2: CGRP00001 | D2: CU00035 | E2: University of Queensland | F2: =LEN(I2) -> 6 | G2: =VLOOKUP(E2,Organisation!$A$2:$C$499,3,FALSE) -> CORG00001 | H2: =VLOOKUP(G2,Organisation!$C$2:$E$318,3,FALSE) -> UQ | I2: CO-ADD | J2: =COUNTIF($I$2:$I$416,I2) -> 1 | K2: info@co-add.org | L2: Community of Open Antimicrobial Drug Discovery (CO-ADD), Institute for Molecular Bioscience | M2: 306 Carmody Road, St. Lucia QLD 4072 | N2: Australia | P2: Open | Q2: 1 | R2: ="Update Collaborator_Group Set Organisation = '"&E2&"' where Group_ID = '"&A2&"'; " -> Update Collaborator_Group Set Organisation = 'University of Queensland' where Group_ID = 'CG00001'; | S2: ="Update Collaborator_Group Set Group_Name = '"&I2&"' where Group_ID = '"&A2&"'; " -> Update Collaborator_Group Set Group_Name = 'CO-ADD' where Group_ID = 'CG00001'; | T2: ="Update dcollab.collab_group Set group_code = '"&I2&"' where Group_ID = '"&B2&"'; " -> Update dcollab.collab_group Set group_code = 'CO-ADD' where Group_ID = 'CGRP00001';
A3: CG00002 | B3: CGRP00002 | D3: CU00139 | E3: University of Queensland | F3: =LEN(I3) -> 10 | G3: =VLOOKUP(E3,Organisation!$A$2:$C$499,3,FALSE) -> CORG00001 | H3: =VLOOKUP(G3,Organisation!$C$2:$E$318,3,FALSE) -> UQ | I3: CooperM_UQ | J3: =COUNTIF($I$2:$I$416,I3) -> 1 | L3: Institute for Molecular Bioscience (IMB) | M3: Bld 80 Carmody Road, St Lucia 4072 | N3: Australia | P3: Open | Q3: 1 | R3: ="Update Collaborator_Group Set Organisation = '"&E3&"' where Group_ID = '"&A3&"'; " -> Update Collaborator_Group Set Organisation = 'University of Queensland' where Group_ID = 'CG00002'; | S3: ="Update Collaborator_Group Set Group_Name = '"&I3&"' where Group_ID = '"&A3&"'; " -> Update Collaborator_Group Set Group_Name = 'CooperM_UQ' where Group_ID = 'CG00002'; | T3: ="Update dcollab.collab_group Set group_code = '"&I3&"' where Group_ID = '"&B3&"'; " -> Update dcollab.collab_group Set group_code = 'CooperM_UQ' where Group_ID = 'CGRP00002';
A4: CG00003 | B4: CGRP00004 | D4: CU00002 | E4: University of Birmingham | F4: =LEN(I4) -> 20 | G4: =VLOOKUP(E4,Organisation!$A$2:$C$499,3,FALSE) -> CORG00218 | H4: =VLOOKUP(G4,Organisation!$C$2:$E$318,3,FALSE) -> UBirmingham | I4: PeacockA_UBirmingham | J4: =COUNTIF($I$2:$I$416,I4) -> 1 | L4: School of Chemistry | N4: United Kingdom | P4: Open | Q4: 1 | R4: ="Update Collaborator_Group Set Organisation = '"&E4&"' where Group_ID = '"&A4&"'; " -> Update Collaborator_Group Set Organisation = 'University of Birmingham' where Group_ID = 'CG00003'; | S4: ="Update Collaborator_Group Set Group_Name = '"&I4&"' where Group_ID = '"&A4&"'; " -> Update Collaborator_Group Set Group_Name = 'PeacockA_UBirmingham' where Group_ID = 'CG00003'; | T4: ="Update dcollab.collab_group Set group_code = '"&I4&"' where Group_ID = '"&B4&"'; " -> Update dcollab.collab_group Set group_code = 'PeacockA_UBirmingham' where Group_ID = 'CGRP00004';
A5: CG00004 | B5: CGRP00005 | D5: CU00005 | E5: University of California San Francisco | F5: =LEN(I5) -> 12 | G5: =VLOOKUP(E5,Organisation!$A$2:$C$499,3,FALSE) -> CORG00222 | H5: =VLOOKUP(G5,Organisation!$C$2:$E$318,3,FALSE) -> UCSF | I5: RensloA_UCSF | J5: =COUNTIF($I$2:$I$416,I5) -> 1 | L5: Department of Pharmaceutical Chemistry | M5: San Francisco | N5: United States of America | P5: Open | Q5: 1 | R5: ="Update Collaborator_Group Set Organisation = '"&E5&"' where Group_ID = '"&A5&"'; " -> Update Collaborator_Group Set Organisation = 'University of California San Francisco' where Group_ID = 'CG00004'; | S5: ="Update Collaborator_Group Set Group_Name = '"&I5&"' where Group_ID = '"&A5&"'; " -> Update Collaborator_Group Set Group_Name = 'RensloA_UCSF' where Group_ID = 'CG00004'; | T5: ="Update dcollab.collab_group Set group_code = '"&I5&"' where Group_ID = '"&B5&"'; " -> Update dcollab.collab_group Set group_code = 'RensloA_UCSF' where Group_ID = 'CGRP00005';
A6: CG00005 | B6: CGRP00006 | D6: CU00006 | E6: Universidade Estadual do Norte Fluminense Darcy Ribeiro | F6: =LEN(I6) -> 18 | G6: =VLOOKUP(E6,Organisation!$A$2:$C$499,3,FALSE) -> CORG00197 | H6: =VLOOKUP(G6,Organisation!$C$2:$E$318,3,FALSE) -> UENorteFluDR | I6: HornA_UENorteFluDR | J6: =COUNTIF($I$2:$I$416,I6) -> 1 | L6: Laboratório de Ciência Químicas | N6: Brazil | P6: Open | Q6: 1 | R6: ="Update Collaborator_Group Set Organisation = '"&E6&"' where Group_ID = '"&A6&"'; " -> Update Collaborator_Group Set Organisation = 'Universidade Estadual do Norte Fluminense Darcy Ribeiro' where Group_ID = 'CG00005'; | S6: ="Update Collaborator_Group Set Group_Name = '"&I6&"' where Group_ID = '"&A6&"'; " -> Update Collaborator_Group Set Group_Name = 'HornA_UENorteFluDR' where Group_ID = 'CG00005'; | T6: ="Update dcollab.collab_group Set group_code = '"&I6&"' where Group_ID = '"&B6&"'; " -> Update dcollab.collab_group Set group_code = 'HornA_UENorteFluDR' where Group_ID = 'CGRP00006';
A7: CG00006 | B7: CGRP00007 | D7: CU00013 | E7: Technical University of Graz | F7: =LEN(I7) -> 18 | G7: =VLOOKUP(E7,Organisation!$A$2:$C$499,3,FALSE) -> CORG00183 | H7: =VLOOKUP(G7,Organisation!$C$2:$E$318,3,FALSE) -> TUGraz | I7: BreinbauerR_TUGraz | J7: =COUNTIF($I$2:$I$416,I7) -> 1 | L7: Institute of Organic Chemistry | N7: Austria | P7: Open | Q7: 1 | R7: ="Update Collaborator_Group Set Organisation = '"&E7&"' where Group_ID = '"&A7&"'; " -> Update Collaborator_Group Set Organisation = 'Technical University of Graz' where Group_ID = 'CG00006'; | S7: ="Update Collaborator_Group Set Group_Name = '"&I7&"' where Group_ID = '"&A7&"'; " -> Update Collaborator_Group Set Group_Name = 'BreinbauerR_TUGraz' where Group_ID = 'CG00006'; | T7: ="Update dcollab.collab_group Set group_code = '"&I7&"' where Group_ID = '"&B7&"'; " -> Update dcollab.collab_group Set group_code = 'BreinbauerR_TUGraz' where Group_ID = 'CGRP00007';
A8: CG00007 | B8: CGRP00008 | D8: CU00015 | E8: University of Strathclyde | F8: =LEN(I8) -> 22 | G8: =VLOOKUP(E8,Organisation!$A$2:$C$499,3,FALSE) -> CORG00270 | H8: =VLOOKUP(G8,Organisation!$C$2:$E$318,3,FALSE) -> UStrathclyde | I8: SucklingC_UStrathclyde | J8: =COUNTIF($I$2:$I$416,I8) -> 1 | L8: Department of Pure and Applied Chemistry | N8: United Kingdom | O8: MTA 25 | P8: Open | Q8: 1 | R8: ="Update Collaborator_Group Set Organisation = '"&E8&"' where Group_ID = '"&A8&"'; " -> Update Collaborator_Group Set Organisation = 'University of Strathclyde' where Group_ID = 'CG00007'; | S8: ="Update Collaborator_Group Set Group_Name = '"&I8&"' where Group_ID = '"&A8&"'; " -> Update Collaborator_Group Set Group_Name = 'SucklingC_UStrathclyde' where Group_ID = 'CG00007'; | T8: ="Update dcollab.collab_group Set group_code = '"&I8&"' where Group_ID = '"&B8&"'; " -> Update dcollab.collab_group Set group_code = 'SucklingC_UStrathclyde' where Group_ID = 'CGRP00008';
A9: CG00008 | B9: CGRP00009 | D9: CU00017 | E9: Trinity College | F9: =LEN(I9) -> 19 | G9: =VLOOKUP(E9,Organisation!$A$2:$C$499,3,FALSE) -> CORG00188 | H9: =VLOOKUP(G9,Organisation!$C$2:$E$318,3,FALSE) -> TrinityCUS | I9: BrindleC_TrinityCUS | J9: =COUNTIF($I$2:$I$416,I9) -> 1 | L9: Department of Chemistry | N9: United States of America | P9: Open | Q9: 1 | R9: ="Update Collaborator_Group Set Organisation = '"&E9&"' where Group_ID = '"&A9&"'; " -> Update Collaborator_Group Set Organisation = 'Trinity College' where Group_ID = 'CG00008'; | S9: ="Update Collaborator_Group Set Group_Name = '"&I9&"' where Group_ID = '"&A9&"'; " -> Update Collaborator_Group Set Group_Name = 'BrindleC_TrinityCUS' where Group_ID = 'CG00008'; | T9: ="Update dcollab.collab_group Set group_code = '"&I9&"' where Group_ID = '"&B9&"'; " -> Update dcollab.collab_group Set group_code = 'BrindleC_TrinityCUS' where Group_ID = 'CGRP00009';
A10: CG00009 | B10: CGRP00010 | D10: CU00020 | E10: University of Sydney | F10: =LEN(I10) -> 16 | G10: =VLOOKUP(E10,Organisation!$A$2:$C$499,3,FALSE) -> CORG00271 | H10: =VLOOKUP(G10,Organisation!$C$2:$E$318,3,FALSE) -> USYD | I10: RichardsonD_USYD | J10: =COUNTIF($I$2:$I$416,I10) -> 1 | L10: School of Medical Sciences | N10: Australia | P10: Open | Q10: 1 | R10: ="Update Collaborator_Group Set Organisation = '"&E10&"' where Group_ID = '"&A10&"'; " -> Update Collaborator_Group Set Organisation = 'University of Sydney' where Group_ID = 'CG00009'; | S10: ="Update Collaborator_Group Set Group_Name = '"&I10&"' where Group_ID = '"&A10&"'; " -> Update Collaborator_Group Set Group_Name = 'RichardsonD_USYD' where Group_ID = 'CG00009'; | T10: ="Update dcollab.collab_group Set group_code = '"&I10&"' where Group_ID = '"&B10&"'; " -> Update dcollab.collab_group Set group_code = 'RichardsonD_USYD' where Group_ID = 'CGRP00010';
A11: CG00010 | B11: CGRP00011 | D11: CU00022 | E11: Saurashtra University | F11: =LEN(I11) -> 18 | G11: =VLOOKUP(E11,Organisation!$A$2:$C$499,3,FALSE) -> CORG00170 | H11: =VLOOKUP(G11,Organisation!$C$2:$E$318,3,FALSE) -> SaurashtraU | I11: ModhaJ_SaurashtraU | J11: =COUNTIF($I$2:$I$416,I11) -> 1 | L11: Maharshi Dayanand Science College | M11: Rajkot | N11: India | P11: Open | Q11: 1 | R11: ="Update Collaborator_Group Set Organisation = '"&E11&"' where Group_ID = '"&A11&"'; " -> Update Collaborator_Group Set Organisation = 'Saurashtra University' where Group_ID = 'CG00010'; | S11: ="Update Collaborator_Group Set Group_Name = '"&I11&"' where Group_ID = '"&A11&"'; " -> Update Collaborator_Group Set Group_Name = 'ModhaJ_SaurashtraU' where Group_ID = 'CG00010'; | T11: ="Update dcollab.collab_group Set group_code = '"&I11&"' where Group_ID = '"&B11&"'; " -> Update dcollab.collab_group Set group_code = 'ModhaJ_SaurashtraU' where Group_ID = 'CGRP00011';
A12: CG00011 | B12: CGRP00012 | D12: CU00023 | E12: Saurashtra University | F12: =LEN(I12) -> 18 | G12: =VLOOKUP(E12,Organisation!$A$2:$C$499,3,FALSE) -> CORG00170 | H12: =VLOOKUP(G12,Organisation!$C$2:$E$318,3,FALSE) -> SaurashtraU | I12: KhuntR_SaurashtraU | J12: =COUNTIF($I$2:$I$416,I12) -> 1 | N12: India | P12: Open | Q12: 1 | R12: ="Update Collaborator_Group Set Organisation = '"&E12&"' where Group_ID = '"&A12&"'; " -> Update Collaborator_Group Set Organisation = 'Saurashtra University' where Group_ID = 'CG00011'; | S12: ="Update Collaborator_Group Set Group_Name = '"&I12&"' where Group_ID = '"&A12&"'; " -> Update Collaborator_Group Set Group_Name = 'KhuntR_SaurashtraU' where Group_ID = 'CG00011'; | T12: ="Update dcollab.collab_group Set group_code = '"&I12&"' where Group_ID = '"&B12&"'; " -> Update dcollab.collab_group Set group_code = 'KhuntR_SaurashtraU' where Group_ID = 'CGRP00012';
A13: CG00012 | B13: CGRP00013 | D13: CU00024 | E13: University of Queensland | F13: =LEN(I13) -> 11 | G13: =VLOOKUP(E13,Organisation!$A$2:$C$499,3,FALSE) -> CORG00001 | H13: =VLOOKUP(G13,Organisation!$C$2:$E$318,3,FALSE) -> UQ | I13: CoulsonE_UQ | J13: =COUNTIF($I$2:$I$416,I13) -> 1 | L13: Queensland Brain Institute | N13: Australia | P13: Open | Q13: 1 | R13: ="Update Collaborator_Group Set Organisation = '"&E13&"' where Group_ID = '"&A13&"'; " -> Update Collaborator_Group Set Organisation = 'University of Queensland' where Group_ID = 'CG00012'; | S13: ="Update Collaborator_Group Set Group_Name = '"&I13&"' where Group_ID = '"&A13&"'; " -> Update Collaborator_Group Set Group_Name = 'CoulsonE_UQ' where Group_ID = 'CG00012'; | T13: ="Update dcollab.collab_group Set group_code = '"&I13&"' where Group_ID = '"&B13&"'; " -> Update dcollab.collab_group Set group_code = 'CoulsonE_UQ' where Group_ID = 'CGRP00013';
A14: CG00013 | B14: CGRP00014 | D14: CU00027 | E14: Deakin University | F14: =LEN(I14) -> 16 | G14: =VLOOKUP(E14,Organisation!$A$2:$C$499,3,FALSE) -> CORG00048 | H14: =VLOOKUP(G14,Organisation!$C$2:$E$318,3,FALSE) -> DeakinU | I14: PfefferF_DeakinU | J14: =COUNTIF($I$2:$I$416,I14) -> 1 | L14: Faculty of Science Engineering & Built Environment | M14: Deakin University | N14: Australia | P14: Open | Q14: 1 | R14: ="Update Collaborator_Group Set Organisation = '"&E14&"' where Group_ID = '"&A14&"'; " -> Update Collaborator_Group Set Organisation = 'Deakin University' where Group_ID = 'CG00013'; | S14: ="Update Collaborator_Group Set Group_Name = '"&I14&"' where Group_ID = '"&A14&"'; " -> Update Collaborator_Group Set Group_Name = 'PfefferF_DeakinU' where Group_ID = 'CG00013'; | T14: ="Update dcollab.collab_group Set group_code = '"&I14&"' where Group_ID = '"&B14&"'; " -> Update dcollab.collab_group Set group_code = 'PfefferF_DeakinU' where Group_ID = 'CGRP00014';
A15: CG00014 | B15: CGRP00015 | D15: CU00028 | E15: Griffith University | F15: =LEN(I15) -> 16 | G15: =VLOOKUP(E15,Organisation!$A$2:$C$499,3,FALSE) -> CORG00067 | H15: =VLOOKUP(G15,Organisation!$C$2:$E$318,3,FALSE) -> GriffithU | I15: GrantG_GriffithU | J15: =COUNTIF($I$2:$I$416,I15) -> 1 | L15: Griffith School of Pharmacy | M15: School of Pharmacy and Pharmacology, Gold Coast Campus, Griffith University, QLD 4222 | N15: Australia | P15: Open | Q15: 1 | R15: ="Update Collaborator_Group Set Organisation = '"&E15&"' where Group_ID = '"&A15&"'; " -> Update Collaborator_Group Set Organisation = 'Griffith University' where Group_ID = 'CG00014'; | S15: ="Update Collaborator_Group Set Group_Name = '"&I15&"' where Group_ID = '"&A15&"'; " -> Update Collaborator_Group Set Group_Name = 'GrantG_GriffithU' where Group_ID = 'CG00014'; | T15: ="Update dcollab.collab_group Set group_code = '"&I15&"' where Group_ID = '"&B15&"'; " -> Update dcollab.collab_group Set group_code = 'GrantG_GriffithU' where Group_ID = 'CGRP00015';
A16: CG00015 | B16: CGRP00016 | D16: CU00464 | E16: University of Queensland | F16: =LEN(I16) -> 8 | G16: =VLOOKUP(E16,Organisation!$A$2:$C$499,3,FALSE) -> CORG00001 | H16: =VLOOKUP(G16,Organisation!$C$2:$E$318,3,FALSE) -> UQ | I16: KingG_UQ | J16: =COUNTIF($I$2:$I$416,I16) -> 1 | L16: Institute for Molecular Bioscience (IMB) | M16: Bld 80, 306 Carmody Road, St Lucia 4072 | N16: Australia | P16: Open | Q16: 1 | R16: ="Update Collaborator_Group Set Organisation = '"&E16&"' where Group_ID = '"&A16&"'; " -> Update Collaborator_Group Set Organisation = 'University of Queensland' where Group_ID = 'CG00015'; | S16: ="Update Collaborator_Group Set Group_Name = '"&I16&"' where Group_ID = '"&A16&"'; " -> Update Collaborator_Group Set Group_Name = 'KingG_UQ' where Group_ID = 'CG00015'; | T16: ="Update dcollab.collab_group Set group_code = '"&I16&"' where Group_ID = '"&B16&"'; " -> Update dcollab.collab_group Set group_code = 'KingG_UQ' where Group_ID = 'CGRP00016';
A17: CG00016 | B17: CGRP00017 | D17: CU00030 | E17: RKDF University | F17: =LEN(I17) -> 14 | G17: =VLOOKUP(E17,Organisation!$A$2:$C$499,3,FALSE) -> CORG00159 | H17: =VLOOKUP(G17,Organisation!$C$2:$E$318,3,FALSE) -> RKDF | I17: BankhedeH_RKDF | J17: =COUNTIF($I$2:$I$416,I17) -> 1 | L17: Pharmaceutics | N17: India | P17: Open | Q17: 1 | R17: ="Update Collaborator_Group Set Organisation = '"&E17&"' where Group_ID = '"&A17&"'; " -> Update Collaborator_Group Set Organisation = 'RKDF University' where Group_ID = 'CG00016'; | S17: ="Update Collaborator_Group Set Group_Name = '"&I17&"' where Group_ID = '"&A17&"'; " -> Update Collaborator_Group Set Group_Name = 'BankhedeH_RKDF' where Group_ID = 'CG00016'; | T17: ="Update dcollab.collab_group Set group_code = '"&I17&"' where Group_ID = '"&B17&"'; " -> Update dcollab.collab_group Set group_code = 'BankhedeH_RKDF' where Group_ID = 'CGRP00017';
A18: CG00017 | B18: CGRP00018 | D18: CU00031 | E18: University of Arizona | F18: =LEN(I18) -> 15 | G18: =VLOOKUP(E18,Organisation!$A$2:$C$499,3,FALSE) -> CORG00214 | H18: =VLOOKUP(G18,Organisation!$C$2:$E$318,3,FALSE) -> UArizona | I18: HulmeC_UArizona | J18: =COUNTIF($I$2:$I$416,I18) -> 1 | L18: College of Pharmacy | M18: BIO5 Translational Drug Discovery Center | N18: United States of America | P18: Open | Q18: 1 | R18: ="Update Collaborator_Group Set Organisation = '"&E18&"' where Group_ID = '"&A18&"'; " -> Update Collaborator_Group Set Organisation = 'University of Arizona' where Group_ID = 'CG00017'; | S18: ="Update Collaborator_Group Set Group_Name = '"&I18&"' where Group_ID = '"&A18&"'; " -> Update Collaborator_Group Set Group_Name = 'HulmeC_UArizona' where Group_ID = 'CG00017'; | T18: ="Update dcollab.collab_group Set group_code = '"&I18&"' where Group_ID = '"&B18&"'; " -> Update dcollab.collab_group Set group_code = 'HulmeC_UArizona' where Group_ID = 'CGRP00018';
A19: CG00018 | B19: CGRP00019 | D19: CU00032 | E19: Imperial College London | F19: =LEN(I19) -> 15 | G19: =VLOOKUP(E19,Organisation!$A$2:$C$499,3,FALSE) -> CORG00075 | H19: =VLOOKUP(G19,Organisation!$C$2:$E$318,3,FALSE) -> ImperialC | I19: BullJ_ImperialC | J19: =COUNTIF($I$2:$I$416,I19) -> 1 | M19: South Kensington Campus, London, SW7 2AZ | N19: United Kingdom | O19: MTA 05 | P19: Restricted | Q19: 1 | R19: ="Update Collaborator_Group Set Organisation = '"&E19&"' where Group_ID = '"&A19&"'; " -> Update Collaborator_Group Set Organisation = 'Imperial College London' where Group_ID = 'CG00018'; | S19: ="Update Collaborator_Group Set Group_Name = '"&I19&"' where Group_ID = '"&A19&"'; " -> Update Collaborator_Group Set Group_Name = 'BullJ_ImperialC' where Group_ID = 'CG00018'; | T19: ="Update dcollab.collab_group Set group_code = '"&I19&"' where Group_ID = '"&B19&"'; " -> Update dcollab.collab_group Set group_code = 'BullJ_ImperialC' where Group_ID = 'CGRP00019';
A20: CG00019 | B20: CGRP00020 | D20: CU00033 | E20: University College London | F20: =LEN(I20) -> 18 | G20: =VLOOKUP(E20,Organisation!$A$2:$C$499,3,FALSE) -> CORG00211 | H20: =VLOOKUP(G20,Organisation!$C$2:$E$318,3,FALSE) -> UCLondon | I20: AndersonJ_UCLondon | J20: =COUNTIF($I$2:$I$416,I20) -> 1 | L20: School of Pharmacy | N20: United Kingdom | O20: MTA 11,12 | P20: Restricted | Q20: 1 | R20: ="Update Collaborator_Group Set Organisation = '"&E20&"' where Group_ID = '"&A20&"'; " -> Update Collaborator_Group Set Organisation = 'University College London' where Group_ID = 'CG00019'; | S20: ="Update Collaborator_Group Set Group_Name = '"&I20&"' where Group_ID = '"&A20&"'; " -> Update Collaborator_Group Set Group_Name = 'AndersonJ_UCLondon' where Group_ID = 'CG00019'; | T20: ="Update dcollab.collab_group Set group_code = '"&I20&"' where Group_ID = '"&B20&"'; " -> Update dcollab.collab_group Set group_code = 'AndersonJ_UCLondon' where Group_ID = 'CGRP00020';
A21: CG00020 | B21: CGRP00021 | D21: CU00034 | E21: University of Auckland | F21: =LEN(I21) -> 20 | G21: =VLOOKUP(E21,Organisation!$A$2:$C$499,3,FALSE) -> CORG00216 | H21: =VLOOKUP(G21,Organisation!$C$2:$E$318,3,FALSE) -> UAuckland | I21: ReynissonJ_UAuckland | J21: =COUNTIF($I$2:$I$416,I21) -> 1 | L21: School of Chemical Science | N21: New Zealand | P21: Open | Q21: 1 | R21: ="Update Collaborator_Group Set Organisation = '"&E21&"' where Group_ID = '"&A21&"'; " -> Update Collaborator_Group Set Organisation = 'University of Auckland' where Group_ID = 'CG00020'; | S21: ="Update Collaborator_Group Set Group_Name = '"&I21&"' where Group_ID = '"&A21&"'; " -> Update Collaborator_Group Set Group_Name = 'ReynissonJ_UAuckland' where Group_ID = 'CG00020'; | T21: ="Update dcollab.collab_group Set group_code = '"&I21&"' where Group_ID = '"&B21&"'; " -> Update dcollab.collab_group Set group_code = 'ReynissonJ_UAuckland' where Group_ID = 'CGRP00021';
A22: CG00021 | B22: CGRP00022 | D22: CU00036 | E22: University of California San Francisco | F22: =LEN(I22) -> 11 | G22: =VLOOKUP(E22,Organisation!$A$2:$C$499,3,FALSE) -> CORG00222 | H22: =VLOOKUP(G22,Organisation!$C$2:$E$318,3,FALSE) -> UCSF | I22: NeitzJ_UCSF | J22: =COUNTIF($I$2:$I$416,I22) -> 1 | L22: Department of Pharmaceutical Chemistry | N22: United States of America | P22: Open | Q22: 1 | R22: ="Update Collaborator_Group Set Organisation = '"&E22&"' where Group_ID = '"&A22&"'; " -> Update Collaborator_Group Set Organisation = 'University of California San Francisco' where Group_ID = 'CG00021'; | S22: ="Update Collaborator_Group Set Group_Name = '"&I22&"' where Group_ID = '"&A22&"'; " -> Update Collaborator_Group Set Group_Name = 'NeitzJ_UCSF' where Group_ID = 'CG00021'; | T22: ="Update dcollab.collab_group Set group_code = '"&I22&"' where Group_ID = '"&B22&"'; " -> Update dcollab.collab_group Set group_code = 'NeitzJ_UCSF' where Group_ID = 'CGRP00022';
A23: CG00022 | B23: CGRP00023 | D23: CU00037 | E23: University of Melbourne | F23: =LEN(I23) -> 16 | G23: =VLOOKUP(E23,Organisation!$A$2:$C$499,3,FALSE) -> CORG00244 | H23: =VLOOKUP(G23,Organisation!$C$2:$E$318,3,FALSE) -> UMelbourne | I23: WadeJ_UMelbourne | J23: =COUNTIF($I$2:$I$416,I23) -> 1 | L23: Florey Institute for Neuroscience & Mental Health | N23: Australia | P23: Open | Q23: 1 | R23: ="Update Collaborator_Group Set Organisation = '"&E23&"' where Group_ID = '"&A23&"'; " -> Update Collaborator_Group Set Organisation = 'University of Melbourne' where Group_ID = 'CG00022'; | S23: ="Update Collaborator_Group Set Group_Name = '"&I23&"' where Group_ID = '"&A23&"'; " -> Update Collaborator_Group Set Group_Name = 'WadeJ_UMelbourne' where Group_ID = 'CG00022'; | T23: ="Update dcollab.collab_group Set group_code = '"&I23&"' where Group_ID = '"&B23&"'; " -> Update dcollab.collab_group Set group_code = 'WadeJ_UMelbourne' where Group_ID = 'CGRP00023';
A24: CG00023 | B24: CGRP00024 | D24: CU00038 | E24: University of Adelaide | F24: =LEN(I24) -> 17 | G24: =VLOOKUP(E24,Organisation!$A$2:$C$499,3,FALSE) -> CORG00212 | H24: =VLOOKUP(G24,Organisation!$C$2:$E$318,3,FALSE) -> UAdelaide | I24: GeorgeJ_UAdelaide | J24: =COUNTIF($I$2:$I$416,I24) -> 1 | L24: Faculty of Chemistry | N24: Australia | P24: Open | Q24: 1 | R24: ="Update Collaborator_Group Set Organisation = '"&E24&"' where Group_ID = '"&A24&"'; " -> Update Collaborator_Group Set Organisation = 'University of Adelaide' where Group_ID = 'CG00023'; | S24: ="Update Collaborator_Group Set Group_Name = '"&I24&"' where Group_ID = '"&A24&"'; " -> Update Collaborator_Group Set Group_Name = 'GeorgeJ_UAdelaide' where Group_ID = 'CG00023'; | T24: ="Update dcollab.collab_group Set group_code = '"&I24&"' where Group_ID = '"&B24&"'; " -> Update dcollab.collab_group Set group_code = 'GeorgeJ_UAdelaide' where Group_ID = 'CGRP00024';
A25: CG00024 | B25: CGRP00025 | D25: CU00039 | E25: Rowan University | F25: =LEN(I25) -> 19 | G25: =VLOOKUP(E25,Organisation!$A$2:$C$499,3,FALSE) -> CORG00162 | H25: =VLOOKUP(G25,Organisation!$C$2:$E$318,3,FALSE) -> RowanU | I25: JonnalgaddaS_RowanU | J25: =COUNTIF($I$2:$I$416,I25) -> 1 | L25: Chemistry and Biochemistry | N25: United States of America | P25: Open | Q25: 1 | R25: ="Update Collaborator_Group Set Organisation = '"&E25&"' where Group_ID = '"&A25&"'; " -> Update Collaborator_Group Set Organisation = 'Rowan University' where Group_ID = 'CG00024'; | S25: ="Update Collaborator_Group Set Group_Name = '"&I25&"' where Group_ID = '"&A25&"'; " -> Update Collaborator_Group Set Group_Name = 'JonnalgaddaS_RowanU' where Group_ID = 'CG00024'; | T25: ="Update dcollab.collab_group Set group_code = '"&I25&"' where Group_ID = '"&B25&"'; " -> Update dcollab.collab_group Set group_code = 'JonnalgaddaS_RowanU' where Group_ID = 'CGRP00025';
A26: CG00025 | B26: CGRP00026 | D26: CU00041 | E26: University of Technology | F26: =LEN(I26) -> 17 | G26: =VLOOKUP(E26,Organisation!$A$2:$C$499,3,FALSE) -> CORG00272 | H26: =VLOOKUP(G26,Organisation!$C$2:$E$318,3,FALSE) -> UTech | I26: OleksyszynJ_UTech | J26: =COUNTIF($I$2:$I$416,I26) -> 1 | L26: Medicinal Chemistry and Microbiology | N26: Poland | P26: Open | Q26: 1 | R26: ="Update Collaborator_Group Set Organisation = '"&E26&"' where Group_ID = '"&A26&"'; " -> Update Collaborator_Group Set Organisation = 'University of Technology' where Group_ID = 'CG00025'; | S26: ="Update Collaborator_Group Set Group_Name = '"&I26&"' where Group_ID = '"&A26&"'; " -> Update Collaborator_Group Set Group_Name = 'OleksyszynJ_UTech' where Group_ID = 'CG00025'; | T26: ="Update dcollab.collab_group Set group_code = '"&I26&"' where Group_ID = '"&B26&"'; " -> Update dcollab.collab_group Set group_code = 'OleksyszynJ_UTech' where Group_ID = 'CGRP00026';
A27: CG00026 | B27: CGRP00027 | D27: CU00042 | E27: University-Hospital Schleswig-Holstein | F27: =LEN(I27) -> 22 | G27: =VLOOKUP(E27,Organisation!$A$2:$C$499,3,FALSE) -> CORG00296 | H27: =VLOOKUP(G27,Organisation!$C$2:$E$318,3,FALSE) -> UHSchleswig | I27: SchroederJ_UHSchleswig | J27: =COUNTIF($I$2:$I$416,I27) -> 1 | L27: Dpt. of Dermatology | M27: Campus Kiel | N27: Germany | P27: Open | Q27: 1 | R27: ="Update Collaborator_Group Set Organisation = '"&E27&"' where Group_ID = '"&A27&"'; " -> Update Collaborator_Group Set Organisation = 'University-Hospital Schleswig-Holstein' where Group_ID = 'CG00026'; | S27: ="Update Collaborator_Group Set Group_Name = '"&I27&"' where Group_ID = '"&A27&"'; " -> Update Collaborator_Group Set Group_Name = 'SchroederJ_UHSchleswig' where Group_ID = 'CG00026'; | T27: ="Update dcollab.collab_group Set group_code = '"&I27&"' where Group_ID = '"&B27&"'; " -> Update dcollab.collab_group Set group_code = 'SchroederJ_UHSchleswig' where Group_ID = 'CGRP00027';
A28: CG00027 | B28: CGRP00028 | D28: CU00043 | E28: CSIR-Indian Institute of Chemical Technology | F28: =LEN(I28) -> 18 | G28: =VLOOKUP(E28,Organisation!$A$2:$C$499,3,FALSE) -> CORG00044 | H28: =VLOOKUP(G28,Organisation!$C$2:$E$318,3,FALSE) -> CSIR-IN | I28: KantevariS_CSIR-IN | J28: =COUNTIF($I$2:$I$416,I28) -> 1 | L28: Academy of Scientific and Innovative Research (AcSIR) | N28: India | P28: Open | Q28: 1 | R28: ="Update Collaborator_Group Set Organisation = '"&E28&"' where Group_ID = '"&A28&"'; " -> Update Collaborator_Group Set Organisation = 'CSIR-Indian Institute of Chemical Technology' where Group_ID = 'CG00027'; | S28: ="Update Collaborator_Group Set Group_Name = '"&I28&"' where Group_ID = '"&A28&"'; " -> Update Collaborator_Group Set Group_Name = 'KantevariS_CSIR-IN' where Group_ID = 'CG00027'; | T28: ="Update dcollab.collab_group Set group_code = '"&I28&"' where Group_ID = '"&B28&"'; " -> Update dcollab.collab_group Set group_code = 'KantevariS_CSIR-IN' where Group_ID = 'CGRP00028';
A29: CG00028 | B29: CGRP00029 | D29: CU00045 | E29: University of Wollongong | F29: =LEN(I29) -> 19 | G29: =VLOOKUP(E29,Organisation!$A$2:$C$499,3,FALSE) -> CORG00292 | H29: =VLOOKUP(G29,Organisation!$C$2:$E$318,3,FALSE) -> UWollongong | I29: KellerP_UWollongong | J29: =COUNTIF($I$2:$I$416,I29) -> 1 | L29: School of Chemistry | M29: Northfields Ave, Wollongong NSW 2522 | N29: Australia | P29: Open | Q29: 1 | R29: ="Update Collaborator_Group Set Organisation = '"&E29&"' where Group_ID = '"&A29&"'; " -> Update Collaborator_Group Set Organisation = 'University of Wollongong' where Group_ID = 'CG00028'; | S29: ="Update Collaborator_Group Set Group_Name = '"&I29&"' where Group_ID = '"&A29&"'; " -> Update Collaborator_Group Set Group_Name = 'KellerP_UWollongong' where Group_ID = 'CG00028'; | T29: ="Update dcollab.collab_group Set group_code = '"&I29&"' where Group_ID = '"&B29&"'; " -> Update dcollab.collab_group Set group_code = 'KellerP_UWollongong' where Group_ID = 'CGRP00029';
A30: CG00029 | B30: CGRP00030 | D30: CU00047 | E30: University of New South Wales | F30: =LEN(I30) -> 12 | G30: =VLOOKUP(E30,Organisation!$A$2:$C$499,3,FALSE) -> CORG00253 | H30: =VLOOKUP(G30,Organisation!$C$2:$E$318,3,FALSE) -> UNSW | I30: HunterL_UNSW | J30: =COUNTIF($I$2:$I$416,I30) -> 1 | L30: School of Chemistry | N30: Australia | P30: Open | Q30: 1 | R30: ="Update Collaborator_Group Set Organisation = '"&E30&"' where Group_ID = '"&A30&"'; " -> Update Collaborator_Group Set Organisation = 'University of New South Wales' where Group_ID = 'CG00029'; | S30: ="Update Collaborator_Group Set Group_Name = '"&I30&"' where Group_ID = '"&A30&"'; " -> Update Collaborator_Group Set Group_Name = 'HunterL_UNSW' where Group_ID = 'CG00029'; | T30: ="Update dcollab.collab_group Set group_code = '"&I30&"' where Group_ID = '"&B30&"'; " -> Update dcollab.collab_group Set group_code = 'HunterL_UNSW' where Group_ID = 'CGRP00030';
A31: CG00030 | B31: CGRP00031 | D31: CU00051 | E31: University of Auckland | F31: =LEN(I31) -> 18 | G31: =VLOOKUP(E31,Organisation!$A$2:$C$499,3,FALSE) -> CORG00216 | H31: =VLOOKUP(G31,Organisation!$C$2:$E$318,3,FALSE) -> UAuckland | I31: BrimbleM_UAuckland | J31: =COUNTIF($I$2:$I$416,I31) -> 1 | L31: School of Chemical Science | N31: New Zealand | P31: Open | Q31: 1 | R31: ="Update Collaborator_Group Set Organisation = '"&E31&"' where Group_ID = '"&A31&"'; " -> Update Collaborator_Group Set Organisation = 'University of Auckland' where Group_ID = 'CG00030'; | S31: ="Update Collaborator_Group Set Group_Name = '"&I31&"' where Group_ID = '"&A31&"'; " -> Update Collaborator_Group Set Group_Name = 'BrimbleM_UAuckland' where Group_ID = 'CG00030'; | T31: ="Update dcollab.collab_group Set group_code = '"&I31&"' where Group_ID = '"&B31&"'; " -> Update dcollab.collab_group Set group_code = 'BrimbleM_UAuckland' where Group_ID = 'CGRP00031';
A32: CG00031 | B32: CGRP00032 | D32: CU00052 | E32: Griffith University | F32: =LEN(I32) -> 17 | G32: =VLOOKUP(E32,Organisation!$A$2:$C$499,3,FALSE) -> CORG00067 | H32: =VLOOKUP(G32,Organisation!$C$2:$E$318,3,FALSE) -> GriffithU | I32: CosterM_GriffithU | J32: =COUNTIF($I$2:$I$416,I32) -> 1 | L32: Eskitis Institute for Drug Discovery | N32: Australia | P32: Open | Q32: 1 | R32: ="Update Collaborator_Group Set Organisation = '"&E32&"' where Group_ID = '"&A32&"'; " -> Update Collaborator_Group Set Organisation = 'Griffith University' where Group_ID = 'CG00031'; | S32: ="Update Collaborator_Group Set Group_Name = '"&I32&"' where Group_ID = '"&A32&"'; " -> Update Collaborator_Group Set Group_Name = 'CosterM_GriffithU' where Group_ID = 'CG00031'; | T32: ="Update dcollab.collab_group Set group_code = '"&I32&"' where Group_ID = '"&B32&"'; " -> Update dcollab.collab_group Set group_code = 'CosterM_GriffithU' where Group_ID = 'CGRP00032';
A33: CG00032 | B33: CGRP00033 | D33: CU00055 | E33: University of Queensland | F33: =LEN(I33) -> 10 | G33: =VLOOKUP(E33,Organisation!$A$2:$C$499,3,FALSE) -> CORG00001 | H33: =VLOOKUP(G33,Organisation!$C$2:$E$318,3,FALSE) -> UQ | I33: TurnerM_UQ | J33: =COUNTIF($I$2:$I$416,I33) -> 1 | L33: School of Agriculture and Food Sciences | N33: Australia | P33: Open | Q33: 1 | R33: ="Update Collaborator_Group Set Organisation = '"&E33&"' where Group_ID = '"&A33&"'; " -> Update Collaborator_Group Set Organisation = 'University of Queensland' where Group_ID = 'CG00032'; | S33: ="Update Collaborator_Group Set Group_Name = '"&I33&"' where Group_ID = '"&A33&"'; " -> Update Collaborator_Group Set Group_Name = 'TurnerM_UQ' where Group_ID = 'CG00032'; | T33: ="Update dcollab.collab_group Set group_code = '"&I33&"' where Group_ID = '"&B33&"'; " -> Update dcollab.collab_group Set group_code = 'TurnerM_UQ' where Group_ID = 'CGRP00033';
A34: CG00033 | B34: CGRP00034 | D34: CU00056 | E34: Arkansas State University Jonesboro | F34: =LEN(I34) -> 16 | G34: =VLOOKUP(E34,Organisation!$A$2:$C$499,3,FALSE) -> CORG00009 | H34: =VLOOKUP(G34,Organisation!$C$2:$E$318,3,FALSE) -> ArkansasSU | I34: AlamM_ArkansasSU | J34: =COUNTIF($I$2:$I$416,I34) -> 1 | L34: Department of Chemistry & Physics | M34: PO Box 419, State University, AR 72467 | N34: United States of America | P34: Open | Q34: 1 | R34: ="Update Collaborator_Group Set Organisation = '"&E34&"' where Group_ID = '"&A34&"'; " -> Update Collaborator_Group Set Organisation = 'Arkansas State University Jonesboro' where Group_ID = 'CG00033'; | S34: ="Update Collaborator_Group Set Group_Name = '"&I34&"' where Group_ID = '"&A34&"'; " -> Update Collaborator_Group Set Group_Name = 'AlamM_ArkansasSU' where Group_ID = 'CG00033'; | T34: ="Update dcollab.collab_group Set group_code = '"&I34&"' where Group_ID = '"&B34&"'; " -> Update dcollab.collab_group Set group_code = 'AlamM_ArkansasSU' where Group_ID = 'CGRP00034';
